<!-- <?xml version='1.0' encoding='utf-8'?> -->
<robot name="Robot">
    <link name="joint1_base">
        <inertial>
            <origin xyz="1.902524107373895e-13 -0.08113229216696756 0.015053258692952614" rpy="0.0 0.0 0.0" />
            <mass value="0.5244703597844238" />
            <inertia ixx="0.0030096279258533427" iyy="0.0008085048644060568" izz="0.0036083125528565707" ixy="2.8807506245027814e-15" iyz="7.219333237994837e-05" ixz="4.2127978351452936e-16" />
        </inertial>
        <visual name="joint1_base_visual">
            <origin xyz="0.0 0.0 0.0" rpy="0.0 0.0 0.0" />
            <geometry>
                <mesh filename="package://my_robot_description/urdf/meshes/joint1_base.stl" scale="0.001 0.001 0.001" />
            </geometry>
        </visual>
        <collision name="joint1_base_collision">
            <origin xyz="0.0 0.0 0.0" rpy="0.0 0.0 0.0" />
            <geometry>
                <mesh filename="package://my_robot_description/urdf/meshes/joint1_base.stl" scale="0.001 0.001 0.001" />
            </geometry>
        </collision>
    </link>
    <link name="joint1_reducer_pulley1">
        <inertial>
            <origin xyz="2.778569200443063e-18 -3.1069506079006714e-09 -4.873086796308712e-09" rpy="0.0 -0.0 2.6101217835531118e-54" />
            <mass value="0.03101910021918258" />
            <inertia ixx="4.2204273007823025e-06" iyy="4.220427300782828e-06" izz="5.237555217799082e-06" ixy="1.6113662872536227e-21" iyz="6.700982677729897e-13" ixz="1.0114711817794002e-21" />
        </inertial>
        <visual name="joint1_reducer_pulley1_visual">
            <origin xyz="5.527363578381955e-18 -3.1069506079006714e-09 -4.873086800749605e-09" rpy="-6.588141389374716e-07 -6.941449148693221e-17 -7.577187207789009e-18" />
            <geometry>
                <mesh filename="package://my_robot_description/urdf/meshes/joint1_reducer_pulley1.stl" scale="0.001 0.001 0.001" />
            </geometry>
        </visual>
        <collision name="joint1_reducer_pulley1_collision">
            <origin xyz="5.527363578381955e-18 -3.1069506079006714e-09 -4.873086800749605e-09" rpy="-6.588141389374716e-07 -6.941449148693221e-17 -7.577187207789009e-18" />
            <geometry>
                <mesh filename="package://my_robot_description/urdf/meshes/joint1_reducer_pulley1.stl" scale="0.001 0.001 0.001" />
            </geometry>
        </collision>
    </link>
    <link name="joint1_reducer_pulley2">
        <inertial>
            <origin xyz="-2.616685388499705e-17 0.017250003949034354 -6.7283784393586885e-09" rpy="0.0 -0.0 0.0" />
            <mass value="0.1298032208716833" />
            <inertia ixx="5.506448828820837e-05" iyy="9.844851178926536e-05" izz="5.506448828823e-05" ixy="5.2709311972197667e-20" iyz="-2.858200798560467e-11" ixz="-2.7018581948623117e-20" />
        </inertial>
        <visual name="joint1_reducer_pulley2_visual">
            <origin xyz="1.0834259121387368e-19 0.017250003949034334 -6.728378402573335e-09" rpy="1.570795667980758 6.300520011547368e-18 1.306553594312218e-16" />
            <geometry>
                <mesh filename="package://my_robot_description/urdf/meshes/joint1_reducer_pulley2.stl" scale="0.001 0.001 0.001" />
            </geometry>
        </visual>
        <collision name="joint1_reducer_pulley2_collision">
            <origin xyz="1.0834259121387368e-19 0.017250003949034334 -6.728378402573335e-09" rpy="1.570795667980758 6.300520011547368e-18 1.306553594312218e-16" />
            <geometry>
                <mesh filename="package://my_robot_description/urdf/meshes/joint1_reducer_pulley2.stl" scale="0.001 0.001 0.001" />
            </geometry>
        </collision>
    </link>
    <link name="joint1_reducer_belt">
        <inertial>
            <origin xyz="2.459387755253715e-17 0.06039681870156227 -3.5841246117662705e-08" rpy="0.0 -0.0 2.6101217835531118e-54" />
            <mass value="0.01783085556459953" />
            <inertia ixx="8.29895143460744e-05" iyy="1.5663783408062494e-05" izz="9.757482074381042e-05" ixy="-1.416054203273387e-19" iyz="5.3964149481029965e-11" ixz="2.3258684346018518e-20" />
        </inertial>
        <visual name="joint1_reducer_belt_visual">
            <origin xyz="1.195417811052492e-17 0.0749999968930659 -4.546202636568353e-08" rpy="-3.1415919947756543 6.939093382459922e-17 3.141592653589793" />
            <geometry>
                <mesh filename="package://my_robot_description/urdf/meshes/joint1_reducer_belt.stl" scale="0.001 0.001 0.001" />
            </geometry>
        </visual>
        <collision name="joint1_reducer_belt_collision">
            <origin xyz="1.195417811052492e-17 0.0749999968930659 -4.546202636568353e-08" rpy="-3.1415919947756543 6.939093382459922e-17 3.141592653589793" />
            <geometry>
                <mesh filename="package://my_robot_description/urdf/meshes/joint1_reducer_belt.stl" scale="0.001 0.001 0.001" />
            </geometry>
        </collision>
    </link>
    <link name="joint2_base">
        <inertial>
            <origin xyz="-2.5032490859845024e-17 -6.666667052055038e-08 -0.09415472911311706" rpy="0.0 -0.0 1.5192908393215678e-64" />
            <mass value="0.3737844747673188" />
            <inertia ixx="0.0021684020512594973" iyy="0.002541480799179775" izz="0.0012019196819413132" ixy="-7.012419469618332e-16" iyz="-8.825212072793048e-10" ixz="9.559402700857931e-18" />
        </inertial>
        <visual name="joint2_base_visual">
            <origin xyz="7.570428180029418e-18 -1.3969306392793992e-07 -0.20499999605091748" rpy="-1.5707969856090356 -6.941147597804719e-17 -7.577187209775712e-18" />
            <geometry>
                <mesh filename="package://my_robot_description/urdf/meshes/joint2_base.stl" scale="0.001 0.001 0.001" />
            </geometry>
        </visual>
        <collision name="joint2_base_collision">
            <origin xyz="7.570428180029418e-18 -1.3969306392793992e-07 -0.20499999605091748" rpy="-1.5707969856090356 -6.941147597804719e-17 -7.577187209775712e-18" />
            <geometry>
                <mesh filename="package://my_robot_description/urdf/meshes/joint2_base.stl" scale="0.001 0.001 0.001" />
            </geometry>
        </collision>
    </link>
    <link name="joint2_frame">
        <inertial>
            <origin xyz="0.033165636066065395 2.1543056420775178e-08 -1.1855422531029443e-17" rpy="-1.5253658785303784e-49 -0.0 0.0" />
            <mass value="0.09195531537657577" />
            <inertia ixx="0.0003984293325053378" iyy="0.0003874187552594606" izz="0.00025847220907580597" ixy="7.253923839693697e-12" iyz="1.2108693119471372e-19" ixz="-1.9349248067374625e-19" />
        </inertial>
        <visual name="joint2_frame_visual">
            <origin xyz="-3.949082554299821e-09 -3.069361175791173e-10 -1.8254522331249485e-17" rpy="1.570795667980758 1.5707963267948963 0" />
            <geometry>
                <mesh filename="package://my_robot_description/urdf/meshes/joint2_frame.stl" scale="0.001 0.001 0.001" />
            </geometry>
        </visual>
        <collision name="joint2_frame_collision">
            <origin xyz="-3.949082554299821e-09 -3.069361175791173e-10 -1.8254522331249485e-17" rpy="1.570795667980758 1.5707963267948963 0" />
            <geometry>
                <mesh filename="package://my_robot_description/urdf/meshes/joint2_frame.stl" scale="0.001 0.001 0.001" />
            </geometry>
        </collision>
    </link>
    <link name="joint2_reducer_pulley1">
        <inertial>
            <origin xyz="-4.164465341460754e-09 0.00032697392925046416 -0.016946000000000058" rpy="0.0 -0.0 0.0" />
            <mass value="0.01367927030145022" />
            <inertia ixx="1.2290355545104784e-06" iyy="1.2290355545105055e-06" izz="1.045431870056414e-06" ixy="-5.454931838422033e-55" iyz="7.940933880509066e-22" ixz="5.636700131359389e-40" />
        </inertial>
        <visual name="joint2_reducer_pulley1_visual">
            <origin xyz="-4.164465341460754e-09 0.00032697392925046416 -0.016946000000000058" rpy="-3.141592653589793 -3.767213823231832e-17 -3.1415919947756548" />
            <geometry>
                <mesh filename="package://my_robot_description/urdf/meshes/joint2_reducer_pulley1.stl" scale="0.001 0.001 0.001" />
            </geometry>
        </visual>
        <collision name="joint2_reducer_pulley1_collision">
            <origin xyz="-4.164465341460754e-09 0.00032697392925046416 -0.016946000000000058" rpy="-3.141592653589793 -3.767213823231832e-17 -3.1415919947756548" />
            <geometry>
                <mesh filename="package://my_robot_description/urdf/meshes/joint2_reducer_pulley1.stl" scale="0.001 0.001 0.001" />
            </geometry>
        </collision>
    </link>
    <link name="joint2_reducer_pulley2">
        <inertial>
            <origin xyz="-3.949082412191274e-09 -3.069361916987015e-10 -0.01174941047403026" rpy="0.0 -0.0 2.6355494858076314e-82" />
            <mass value="0.1436820712066979" />
            <inertia ixx="6.672582947984525e-05" iyy="6.672582947984775e-05" izz="0.00012054367455659187" ixy="3.4037489589822016e-19" iyz="2.3134587371883075e-20" ixz="4.841619478135378e-38" />
        </inertial>
        <visual name="joint2_reducer_pulley2_visual">
            <origin xyz="-3.949082412191274e-09 -3.069361442244699e-10 -0.011749410474030251" rpy="-3.141592653589793 2.357438558136164e-17 -3.1415919947756543" />
            <geometry>
                <mesh filename="package://my_robot_description/urdf/meshes/joint2_reducer_pulley2.stl" scale="0.001 0.001 0.001" />
            </geometry>
        </visual>
        <collision name="joint2_reducer_pulley2_collision">
            <origin xyz="-3.949082412191274e-09 -3.069361442244699e-10 -0.011749410474030251" rpy="-3.141592653589793 2.357438558136164e-17 -3.1415919947756543" />
            <geometry>
                <mesh filename="package://my_robot_description/urdf/meshes/joint2_reducer_pulley2.stl" scale="0.001 0.001 0.001" />
            </geometry>
        </collision>
    </link>
    <link name="joint2_reducer_belt">
        <inertial>
            <origin xyz="0.09792616230656273 6.209201523037374e-08 -0.01677500000000003" rpy="0.0 -0.0 0.0" />
            <mass value="0.017821959225066717" />
            <inertia ixx="1.5528456657875134e-05" iyy="8.206902714501089e-05" izz="9.651954487660693e-05" ixy="-4.383786861004659e-11" iyz="-4.5568139174627465e-20" ixz="2.710505431213761e-20" />
        </inertial>
        <visual name="joint2_reducer_belt_visual">
            <origin xyz="0.07999999605093387 5.028200351693129e-08 -0.01677500000000003" rpy="-5.970872957508353e-17 3.0737625076938353e-17 6.588141386044049e-07" />
            <geometry>
                <mesh filename="package://my_robot_description/urdf/meshes/joint2_reducer_belt.stl" scale="0.001 0.001 0.001" />
            </geometry>
        </visual>
        <collision name="joint2_reducer_belt_collision">
            <origin xyz="0.07999999605093387 5.028200351693129e-08 -0.01677500000000003" rpy="-5.970872957508353e-17 3.0737625076938353e-17 6.588141386044049e-07" />
            <geometry>
                <mesh filename="package://my_robot_description/urdf/meshes/joint2_reducer_belt.stl" scale="0.001 0.001 0.001" />
            </geometry>
        </collision>
    </link>
    <link name="joint3_base">
        <inertial>
            <origin xyz="-1.761897702949151e-16 5.7133830761309745e-08 0.09415472911303831" rpy="0.0 -0.0 0.0" />
            <mass value="0.3737844747673188" />
            <inertia ixx="0.0021684020512595104" iyy="0.0025414807991797905" izz="0.0012019196819413153" ixy="7.014399450499691e-16" iyz="-8.825212052118682e-10" ixz="-8.630966317896395e-18" />
        </inertial>
        <visual name="joint3_base_visual">
            <origin xyz="-2.446843675355284e-16 1.301602241287036e-07 0.20499999605083885" rpy="1.5707956679807582 -8.495921535036531e-16 7.575976889877827e-18" />
            <geometry>
                <mesh filename="package://my_robot_description/urdf/meshes/joint3_base.stl" scale="0.001 0.001 0.001" />
            </geometry>
        </visual>
        <collision name="joint3_base_collision">
            <origin xyz="-2.446843675355284e-16 1.301602241287036e-07 0.20499999605083885" rpy="1.5707956679807582 -8.495921535036531e-16 7.575976889877827e-18" />
            <geometry>
                <mesh filename="package://my_robot_description/urdf/meshes/joint3_base.stl" scale="0.001 0.001 0.001" />
            </geometry>
        </collision>
    </link>
    <link name="joint3_frame">
        <inertial>
            <origin xyz="0.03316563606598656 -2.2010216772992258e-08 -2.6819560793150943e-16" rpy="4.930380657631324e-32 -0.0 0.0" />
            <mass value="0.09195531537657577" />
            <inertia ixx="0.0003984293325053378" iyy="0.000387418755259458" izz="0.0002584722090758076" ixy="-7.253923962732298e-12" iyz="1.7607674013066132e-19" ixz="1.3502094759266816e-19" />
        </inertial>
        <visual name="joint3_frame_visual">
            <origin xyz="-3.949161424543491e-09 -1.6022425304866496e-10 -2.447104307781268e-16" rpy="-1.5707969856090347 -1.5707963267948961 0" />
            <geometry>
                <mesh filename="package://my_robot_description/urdf/meshes/joint3_frame.stl" scale="0.001 0.001 0.001" />
            </geometry>
        </visual>
        <collision name="joint3_frame_collision">
            <origin xyz="-3.949161424543491e-09 -1.6022425304866496e-10 -2.447104307781268e-16" rpy="-1.5707969856090347 -1.5707963267948961 0" />
            <geometry>
                <mesh filename="package://my_robot_description/urdf/meshes/joint3_frame.stl" scale="0.001 0.001 0.001" />
            </geometry>
        </collision>
    </link>
    <link name="joint3_miter_gear_center">
        <inertial>
            <origin xyz="2.182469529873162e-12 7.639248874262412e-09 0.016145975052642713" rpy="0.0 -0.0 0.0" />
            <mass value="0.1437313784400598" />
            <inertia ixx="7.542521211722358e-05" iyy="7.542521202681671e-05" izz="0.00013181706785530067" ixy="1.4048415345023643e-14" iyz="3.713959465287995e-11" ixz="1.996326203514157e-15" />
        </inertial>
        <visual name="joint3_miter_gear_center_visual">
            <origin xyz="-2.446787956631673e-16 3.983981277510981e-08 0.06500006022416102" rpy="6.588141376052046e-07 -4.549765631508409e-16 3.141592653589793" />
            <geometry>
                <mesh filename="package://my_robot_description/urdf/meshes/joint3_miter_gear_center.stl" scale="0.001 0.001 0.001" />
            </geometry>
        </visual>
        <collision name="joint3_miter_gear_center_collision">
            <origin xyz="-2.446787956631673e-16 3.983981277510981e-08 0.06500006022416102" rpy="6.588141376052046e-07 -4.549765631508409e-16 3.141592653589793" />
            <geometry>
                <mesh filename="package://my_robot_description/urdf/meshes/joint3_miter_gear_center.stl" scale="0.001 0.001 0.001" />
            </geometry>
        </collision>
    </link>
    <link name="joint3_miter_gear_left">
        <inertial>
            <origin xyz="-3.943978583720309e-09 1.6119994388267243e-10 0.011520815678886588" rpy="-2.465190328815662e-32 2.138211768073757e-50 0.0" />
            <mass value="0.08604042921067255" />
            <inertia ixx="4.647452402651847e-05" iyy="4.6474524042473806e-05" izz="8.999113426298722e-05" ixy="-3.22453452871297e-15" iyz="1.3299072134895384e-16" ixz="4.514617846229635e-16" />
        </inertial>
        <visual name="joint3_miter_gear_left_visual">
            <origin xyz="-3.949161495597764e-09 1.602242001908275e-10 0.05469705627500024" rpy="4.923643382238508e-16 7.195332789816743e-17 -1.505345821030971" />
            <geometry>
                <mesh filename="package://my_robot_description/urdf/meshes/joint3_miter_gear_left.stl" scale="0.001 0.001 0.001" />
            </geometry>
        </visual>
        <collision name="joint3_miter_gear_left_collision">
            <origin xyz="-3.949161495597764e-09 1.602242001908275e-10 0.05469705627500024" rpy="4.923643382238508e-16 7.195332789816743e-17 -1.505345821030971" />
            <geometry>
                <mesh filename="package://my_robot_description/urdf/meshes/joint3_miter_gear_left.stl" scale="0.001 0.001 0.001" />
            </geometry>
        </collision>
    </link>
    <link name="joint3_miter_gear_right">
        <inertial>
            <origin xyz="-3.954344336420945e-09 -1.6119998110780534e-10 0.011520815678886073" rpy="2.465190328815662e-32 -2.138211768073757e-50 0.0" />
            <mass value="0.08604042921067255" />
            <inertia ixx="4.647452402651858e-05" iyy="4.6474524042473806e-05" izz="8.999113426298722e-05" ixy="-3.224476229023397e-15" iyz="-1.3299419054444288e-16" ixz="-4.514617846229635e-16" />
        </inertial>
        <visual name="joint3_miter_gear_right_visual">
            <origin xyz="-3.949161424543491e-09 -1.6022424459974848e-10 0.05469705627499974" rpy="4.650460114336658e-16 8.346791427749373e-17 1.636245514930546" />
            <geometry>
                <mesh filename="package://my_robot_description/urdf/meshes/joint3_miter_gear_right.stl" scale="0.001 0.001 0.001" />
            </geometry>
        </visual>
        <collision name="joint3_miter_gear_right_collision">
            <origin xyz="-3.949161424543491e-09 -1.6022424459974848e-10 0.05469705627499974" rpy="4.650460114336658e-16 8.346791427749373e-17 1.636245514930546" />
            <geometry>
                <mesh filename="package://my_robot_description/urdf/meshes/joint3_miter_gear_right.stl" scale="0.001 0.001 0.001" />
            </geometry>
        </collision>
    </link>
    <link name="joint3_left_belt">
        <inertial>
            <origin xyz="0.09792616230648371 6.255917560712821e-08 -0.016774999999999825" rpy="1.0947644252537633e-47 3.421138828918011e-49 0.0" />
            <mass value="0.017821959225066717" />
            <inertia ixx="1.55284566578751e-05" iyy="8.206902714501249e-05" izz="9.651954487660715e-05" ixy="-4.3837868584270803e-11" iyz="-4.495809347286959e-20" ixz="-1.7713984262332962e-37" />
        </inertial>
        <visual name="joint3_left_belt_visual">
            <origin xyz="0.07999999605085485 5.0749163898661295e-08 -0.016774999999999835" rpy="-5.276985391332613e-17 -8.883051664436927e-16 6.588141383268496e-07" />
            <geometry>
                <mesh filename="package://my_robot_description/urdf/meshes/joint3_left_belt.stl" scale="0.001 0.001 0.001" />
            </geometry>
        </visual>
        <collision name="joint3_left_belt_collision">
            <origin xyz="0.07999999605085485 5.0749163898661295e-08 -0.016774999999999835" rpy="-5.276985391332613e-17 -8.883051664436927e-16 6.588141383268496e-07" />
            <geometry>
                <mesh filename="package://my_robot_description/urdf/meshes/joint3_left_belt.stl" scale="0.001 0.001 0.001" />
            </geometry>
        </collision>
    </link>
    <link name="joint3_left_pulley1">
        <inertial>
            <origin xyz="-4.164544264995129e-09 0.0003269743964108026 -0.016945999999999906" rpy="1.0947644252537633e-47 3.421138828918011e-49 0.0" />
            <mass value="0.01367927030145022" />
            <inertia ixx="1.2290355545104644e-06" iyy="1.2290355545108846e-06" izz="1.045431870056509e-06" ixy="-1.0689696373403846e-50" iyz="-7.940933880509064e-22" ixz="-1.0842021724855043e-19" />
        </inertial>
        <visual name="joint3_left_pulley1_visual">
            <origin xyz="-4.164544264995129e-09 0.0003269743964108026 -0.016945999999999906" rpy="9.680191244159165e-18 -8.882577392160941e-16 6.588141381880714e-07" />
            <geometry>
                <mesh filename="package://my_robot_description/urdf/meshes/joint3_left_pulley1.stl" scale="0.001 0.001 0.001" />
            </geometry>
        </visual>
        <collision name="joint3_left_pulley1_collision">
            <origin xyz="-4.164544264995129e-09 0.0003269743964108026 -0.016945999999999906" rpy="9.680191244159165e-18 -8.882577392160941e-16 6.588141381880714e-07" />
            <geometry>
                <mesh filename="package://my_robot_description/urdf/meshes/joint3_left_pulley1.stl" scale="0.001 0.001 0.001" />
            </geometry>
        </collision>
    </link>
    <link name="joint3_left_pulley2">
        <inertial>
            <origin xyz="-3.949161353489217e-09 1.6022407234739938e-10 -0.011749410474029994" rpy="0.0 2.138211768073757e-50 0.0" />
            <mass value="0.1436820712066979" />
            <inertia ixx="6.672582947984558e-05" iyy="6.672582947984254e-05" izz="0.00012054367455658493" ixy="-3.200064004947144e-19" iyz="-3.0511384074630967e-20" ixz="-3.5701405721862936e-38" />
        </inertial>
        <visual name="joint3_left_pulley2_visual">
            <origin xyz="-3.949161353489217e-09 1.60224119821902e-10 -0.011749410474030003" rpy="-5.970874780786299e-17 -4.3010495679263476e-16 6.588141382713378e-07" />
            <geometry>
                <mesh filename="package://my_robot_description/urdf/meshes/joint3_left_pulley2.stl" scale="0.001 0.001 0.001" />
            </geometry>
        </visual>
        <collision name="joint3_left_pulley2_collision">
            <origin xyz="-3.949161353489217e-09 1.60224119821902e-10 -0.011749410474030003" rpy="-5.970874780786299e-17 -4.3010495679263476e-16 6.588141382713378e-07" />
            <geometry>
                <mesh filename="package://my_robot_description/urdf/meshes/joint3_left_pulley2.stl" scale="0.001 0.001 0.001" />
            </geometry>
        </collision>
    </link>
    <link name="joint3_right_belt">
        <inertial>
            <origin xyz="0.09792616230648371 -6.255917560414314e-08 -0.016775000000000217" rpy="1.0947644252537633e-47 -3.421138828918011e-49 0.0" />
            <mass value="0.017821959225066717" />
            <inertia ixx="1.5528456657875113e-05" iyy="8.206902714501249e-05" izz="9.651954487660628e-05" ixy="4.383786858780452e-11" iyz="-4.4348874951724284e-20" ixz="1.0842021724855043e-19" />
        </inertial>
        <visual name="joint3_right_belt_visual">
            <origin xyz="0.07999999605085485 -5.0749163898661295e-08 -0.016775000000000206" rpy="3.141592653589793 8.882645088622278e-16 -6.588141381603162e-07" />
            <geometry>
                <mesh filename="package://my_robot_description/urdf/meshes/joint3_right_belt.stl" scale="0.001 0.001 0.001" />
            </geometry>
        </visual>
        <collision name="joint3_right_belt_collision">
            <origin xyz="0.07999999605085485 -5.0749163898661295e-08 -0.016775000000000206" rpy="3.141592653589793 8.882645088622278e-16 -6.588141381603162e-07" />
            <geometry>
                <mesh filename="package://my_robot_description/urdf/meshes/joint3_right_belt.stl" scale="0.001 0.001 0.001" />
            </geometry>
        </collision>
    </link>
    <link name="joint3_right_pulley1">
        <inertial>
            <origin xyz="-4.164544336049403e-09 -0.00032697439641085147 -0.016946000000000155" rpy="1.0947644252537633e-47 -3.421138828918011e-49 0.0" />
            <mass value="0.01367927030145022" />
            <inertia ixx="1.2290355545104644e-06" iyy="1.2290355545108846e-06" izz="1.045431870056509e-06" ixy="1.5441292269262408e-54" iyz="8.999725064576941e-22" ixz="2.706767146144951e-39" />
        </inertial>
        <visual name="joint3_right_pulley1_visual">
            <origin xyz="-4.164544336049403e-09 -0.00032697439641085147 -0.016946000000000155" rpy="-2.741302487638864e-18 -8.813164564145778e-16 3.1415919947756548" />
            <geometry>
                <mesh filename="package://my_robot_description/urdf/meshes/joint3_right_pulley1.stl" scale="0.001 0.001 0.001" />
            </geometry>
        </visual>
        <collision name="joint3_right_pulley1_collision">
            <origin xyz="-4.164544336049403e-09 -0.00032697439641085147 -0.016946000000000155" rpy="-2.741302487638864e-18 -8.813164564145778e-16 3.1415919947756548" />
            <geometry>
                <mesh filename="package://my_robot_description/urdf/meshes/joint3_right_pulley1.stl" scale="0.001 0.001 0.001" />
            </geometry>
        </collision>
    </link>
    <link name="joint3_right_pulley2">
        <inertial>
            <origin xyz="-3.949161140326396e-09 -1.6022416116524136e-10 -0.01174941047403049" rpy="0.0 -2.138211768073757e-50 0.0" />
            <mass value="0.1436820712066979" />
            <inertia ixx="6.672582947984558e-05" iyy="6.672582947985642e-05" izz="0.00012054367455659881" ixy="-3.4869964158295383e-19" iyz="2.5629364099343012e-20" ixz="1.7347234759768069e-18" />
        </inertial>
        <visual name="joint3_right_pulley2_visual">
            <origin xyz="-3.9491610692721225e-09 -1.6022420863974398e-10 -0.01174941047403051" rpy="1.1136485329104199e-17 -4.231771934310535e-16 3.1415919947756548" />
            <geometry>
                <mesh filename="package://my_robot_description/urdf/meshes/joint3_right_pulley2.stl" scale="0.001 0.001 0.001" />
            </geometry>
        </visual>
        <collision name="joint3_right_pulley2_collision">
            <origin xyz="-3.9491610692721225e-09 -1.6022420863974398e-10 -0.01174941047403051" rpy="1.1136485329104199e-17 -4.231771934310535e-16 3.1415919947756548" />
            <geometry>
                <mesh filename="package://my_robot_description/urdf/meshes/joint3_right_pulley2.stl" scale="0.001 0.001 0.001" />
            </geometry>
        </collision>
    </link>
    <link name="Link_B">
        <inertial>
            <origin xyz="-1.5773551702798203e-17 0.047499996050893285 -3.380965437265978e-08" rpy="-4.930380657631325e-32 -1.8205836749514715e-49 0.0" />
            <mass value="0.8953539062730913" />
            <inertia ixx="0.001232976941763539" iyy="0.0011191923828413987" izz="0.0012329769417635385" ixy="9.349047189615446e-19" iyz="7.496287545700255e-11" ixz="-5.024068871975146e-19" />
        </inertial>
        <visual name="Link_B_visual">
            <origin xyz="-2.1868312860821388e-17 0.047499996050893285 -3.3809654366564935e-08" rpy="-1.5707969856090354 6.370754102429776e-19 8.553519775449855e-16" />
            <geometry>
                <mesh filename="package://my_robot_description/urdf/meshes/Link_B.stl" scale="0.001 0.001 0.001" />
            </geometry>
        </visual>
        <collision name="Link_B_collision">
            <origin xyz="-2.1868312860821388e-17 0.047499996050893285 -3.3809654366564935e-08" rpy="-1.5707969856090354 6.370754102429776e-19 8.553519775449855e-16" />
            <geometry>
                <mesh filename="package://my_robot_description/urdf/meshes/Link_B.stl" scale="0.001 0.001 0.001" />
            </geometry>
        </collision>
    </link>
    <link name="joint4_base">
        <inertial>
            <origin xyz="-3.9703486914468804e-16 5.760099166077896e-08 0.09415472911296022" rpy="0.0 -0.0 0.0" />
            <mass value="0.3737844747673188" />
            <inertia ixx="0.002168402051259455" iyy="0.0025414807991798174" izz="0.0012019196819413119" ixy="7.01093433381458e-16" iyz="-8.825212049139772e-10" ixz="-9.01452702430087e-18" />
        </inertial>
        <visual name="joint4_base_visual">
            <origin xyz="-4.21535262732262e-16 1.306273849789476e-07 0.20499999605076055" rpy="1.5707956679807586 -4.526996525618286e-16 7.576499569624125e-18" />
            <geometry>
                <mesh filename="package://my_robot_description/urdf/meshes/joint4_base.stl" scale="0.001 0.001 0.001" />
            </geometry>
        </visual>
        <collision name="joint4_base_collision">
            <origin xyz="-4.21535262732262e-16 1.306273849789476e-07 0.20499999605076055" rpy="1.5707956679807586 -4.526996525618286e-16 7.576499569624125e-18" />
            <geometry>
                <mesh filename="package://my_robot_description/urdf/meshes/joint4_base.stl" scale="0.001 0.001 0.001" />
            </geometry>
        </collision>
    </link>
    <link name="joint4_miter_gear_center">
        <inertial>
            <origin xyz="2.1817558174341733e-12 0.016145975052720588 -7.172087854722553e-09" rpy="0.0 -0.0 0.0" />
            <mass value="0.1437313784400598" />
            <inertia ixx="7.542521211723052e-05" iyy="0.00013181706785530092" izz="7.542521202683059e-05" ixy="1.994506202499921e-15" iyz="-3.7139594430083815e-11" ixz="-1.404834562655424e-14" />
        </inertial>
        <visual name="joint4_miter_gear_center_visual">
            <origin xyz="-2.5877065934138944e-15 0.06500006022423889 -3.937265177387549e-08" rpy="1.5707969856090351 1.1864291130330307e-16 -3.1415926535897603" />
            <geometry>
                <mesh filename="package://my_robot_description/urdf/meshes/joint4_miter_gear_center.stl" scale="0.001 0.001 0.001" />
            </geometry>
        </visual>
        <collision name="joint4_miter_gear_center_collision">
            <origin xyz="-2.5877065934138944e-15 0.06500006022423889 -3.937265177387549e-08" rpy="1.5707969856090351 1.1864291130330307e-16 -3.1415926535897603" />
            <geometry>
                <mesh filename="package://my_robot_description/urdf/meshes/joint4_miter_gear_center.stl" scale="0.001 0.001 0.001" />
            </geometry>
        </collision>
    </link>
    <link name="joint4_miter_gear_left">
        <inertial>
            <origin xyz="-3.944056743421243e-09 6.283608343413507e-10 0.01152081567888664" rpy="1.1128055214186653e-82 -0.0 0.0" />
            <mass value="0.08604042921067255" />
            <inertia ixx="4.6474524026518185e-05" iyy="4.647452404246688e-05" izz="8.999113426298722e-05" ixy="-3.224506781766503e-15" iyz="1.329720423699515e-16" ixz="4.514617846229636e-16" />
        </inertial>
        <visual name="joint4_miter_gear_left_visual">
            <origin xyz="-3.949239584244424e-09 6.273850948436063e-10 0.05469705627500031" rpy="1.723012445927283e-16 -1.1538285659769e-16 -1.5053458210309716" />
            <geometry>
                <mesh filename="package://my_robot_description/urdf/meshes/joint4_miter_gear_left.stl" scale="0.001 0.001 0.001" />
            </geometry>
        </visual>
        <collision name="joint4_miter_gear_left_collision">
            <origin xyz="-3.949239584244424e-09 6.273850948436063e-10 0.05469705627500031" rpy="1.723012445927283e-16 -1.1538285659769e-16 -1.5053458210309716" />
            <geometry>
                <mesh filename="package://my_robot_description/urdf/meshes/joint4_miter_gear_left.stl" scale="0.001 0.001 0.001" />
            </geometry>
        </collision>
    </link>
    <link name="joint4_miter_gear_right">
        <inertial>
            <origin xyz="-3.9544227092847e-09 -6.283609258619731e-10 0.011520815678885877" rpy="-1.1128055214186653e-82 -0.0 0.0" />
            <mass value="0.08604042921067255" />
            <inertia ixx="4.647452402651824e-05" iyy="4.647452404248076e-05" izz="8.999113426297334e-05" ixy="-3.224501209877897e-15" iyz="-1.3301686852811666e-16" ixz="-4.510281037539694e-16" />
        </inertial>
        <visual name="joint4_miter_gear_right_visual">
            <origin xyz="-3.949239868461518e-09 -6.273851836614483e-10 0.054697056274999545" rpy="1.3460153959550908e-16 3.7490071412796176e-16 1.6362455149305462" />
            <geometry>
                <mesh filename="package://my_robot_description/urdf/meshes/joint4_miter_gear_right.stl" scale="0.001 0.001 0.001" />
            </geometry>
        </visual>
        <collision name="joint4_miter_gear_right_collision">
            <origin xyz="-3.949239868461518e-09 -6.273851836614483e-10 0.054697056274999545" rpy="1.3460153959550908e-16 3.7490071412796176e-16 1.6362455149305462" />
            <geometry>
                <mesh filename="package://my_robot_description/urdf/meshes/joint4_miter_gear_right.stl" scale="0.001 0.001 0.001" />
            </geometry>
        </collision>
    </link>
    <link name="joint4_left_belt">
        <inertial>
            <origin xyz="0.0979261623064059 6.302633607388868e-08 -0.01677499999999963" rpy="0.0 -0.0 0.0" />
            <mass value="0.017821959225066717" />
            <inertia ixx="1.5528456657875066e-05" iyy="8.206902714501078e-05" izz="9.651954487660368e-05" ixy="-4.383786856254409e-11" iyz="-4.3230940353858885e-20" ixz="-6.493411430674704e-38" />
        </inertial>
        <visual name="joint4_left_belt_visual">
            <origin xyz="0.07999999605077704 5.121632437587022e-08 -0.01677499999999962" rpy="-2.501429532668887e-17 -4.913804364991974e-16 6.588141377439826e-07" />
            <geometry>
                <mesh filename="package://my_robot_description/urdf/meshes/joint4_left_belt.stl" scale="0.001 0.001 0.001" />
            </geometry>
        </visual>
        <collision name="joint4_left_belt_collision">
            <origin xyz="0.07999999605077704 5.121632437587022e-08 -0.01677499999999962" rpy="-2.501429532668887e-17 -4.913804364991974e-16 6.588141377439826e-07" />
            <geometry>
                <mesh filename="package://my_robot_description/urdf/meshes/joint4_left_belt.stl" scale="0.001 0.001 0.001" />
            </geometry>
        </collision>
    </link>
    <link name="joint4_left_pulley1">
        <inertial>
            <origin xyz="-4.1646237036729875e-09 0.0003269748635715107 -0.016945999999999677" rpy="0.0 -0.0 0.0" />
            <mass value="0.01367927030145022" />
            <inertia ixx="1.2290355545104648e-06" iyy="1.229035554510885e-06" izz="1.0454318700569426e-06" ixy="-4.235164736271502e-22" iyz="-7.940933880509066e-22" ixz="-9.166099684873342e-40" />
        </inertial>
        <visual name="joint4_left_pulley1_visual">
            <origin xyz="-4.1646237036729875e-09 0.0003269748635715107 -0.016945999999999677" rpy="2.3557961998171735e-17 -4.775016448857633e-16 6.588141378827602e-07" />
            <geometry>
                <mesh filename="package://my_robot_description/urdf/meshes/joint4_left_pulley1.stl" scale="0.001 0.001 0.001" />
            </geometry>
        </visual>
        <collision name="joint4_left_pulley1_collision">
            <origin xyz="-4.1646237036729875e-09 0.0003269748635715107 -0.016945999999999677" rpy="2.3557961998171735e-17 -4.775016448857633e-16 6.588141378827602e-07" />
            <geometry>
                <mesh filename="package://my_robot_description/urdf/meshes/joint4_left_pulley1.stl" scale="0.001 0.001 0.001" />
            </geometry>
        </collision>
    </link>
    <link name="joint4_left_pulley2">
        <inertial>
            <origin xyz="-3.94924029478716e-09 6.273850735817241e-10 -0.011749410474029852" rpy="0.0 -0.0 0.0" />
            <mass value="0.1436820712066979" />
            <inertia ixx="6.672582947984517e-05" iyy="6.672582947983563e-05" izz="0.000120543674556578" ixy="-3.375955690400421e-19" iyz="-2.786275175323619e-20" ixz="-1.734723475976807e-18" />
        </inertial>
        <visual name="joint4_left_pulley2_visual">
            <origin xyz="-3.94924029478716e-09 6.273851210560912e-10 -0.011749410474029852" rpy="-2.3318111246450424e-16 -6.88327700403622e-17 6.588141377439826e-07" />
            <geometry>
                <mesh filename="package://my_robot_description/urdf/meshes/joint4_left_pulley2.stl" scale="0.001 0.001 0.001" />
            </geometry>
        </visual>
        <collision name="joint4_left_pulley2_collision">
            <origin xyz="-3.94924029478716e-09 6.273851210560912e-10 -0.011749410474029852" rpy="-2.3318111246450424e-16 -6.88327700403622e-17 6.588141377439826e-07" />
            <geometry>
                <mesh filename="package://my_robot_description/urdf/meshes/joint4_left_pulley2.stl" scale="0.001 0.001 0.001" />
            </geometry>
        </collision>
    </link>
    <link name="Link_A">
        <inertial>
            <origin xyz="-2.931034929731999e-16 0.0474999960508147 -3.427681497421395e-08" rpy="-4.930380657631325e-32 1.4495192703312503e-49 -4.276423536147513e-50" />
            <mass value="0.8953539062730913" />
            <inertia ixx="0.0012329769417634417" iyy="0.0011191923828413985" izz="0.0012329769417634968" ixy="8.89098174969472e-19" iyz="7.496287514238275e-11" ixz="-4.339638893498613e-19" />
        </inertial>
        <visual name="Link_A_visual">
            <origin xyz="-2.9919825413122313e-16 0.0474999960508147 -3.427681496811924e-08" rpy="-1.5707969856090351 6.376056374001912e-19 4.52692882915708e-16" />
            <geometry>
                <mesh filename="package://my_robot_description/urdf/meshes/Link_A.stl" scale="0.001 0.001 0.001" />
            </geometry>
        </visual>
        <collision name="Link_A_collision">
            <origin xyz="-2.9919825413122313e-16 0.0474999960508147 -3.427681496811924e-08" rpy="-1.5707969856090351 6.376056374001912e-19 4.52692882915708e-16" />
            <geometry>
                <mesh filename="package://my_robot_description/urdf/meshes/Link_A.stl" scale="0.001 0.001 0.001" />
            </geometry>
        </collision>
    </link>
    <link name="joint4_right_belt">
        <inertial>
            <origin xyz="0.09792616230640562 -6.302633615631257e-08 -0.01677500000000044" rpy="0.0 -0.0 0.0" />
            <mass value="0.017821959225066717" />
            <inertia ixx="1.5528456657875093e-05" iyy="8.206902714500731e-05" izz="9.651954487660368e-05" ixy="4.383786855959271e-11" iyz="-4.384036567015733e-20" ixz="6.493411430674704e-38" />
        </inertial>
        <visual name="joint4_right_belt_visual">
            <origin xyz="0.07999999605077676 -5.121632445580628e-08 -0.01677500000000044" rpy="3.141592653589793 4.913939910723587e-16 -6.588141378827602e-07" />
            <geometry>
                <mesh filename="package://my_robot_description/urdf/meshes/joint4_right_belt.stl" scale="0.001 0.001 0.001" />
            </geometry>
        </visual>
        <collision name="joint4_right_belt_collision">
            <origin xyz="0.07999999605077676 -5.121632445580628e-08 -0.01677500000000044" rpy="3.141592653589793 4.913939910723587e-16 -6.588141378827602e-07" />
            <geometry>
                <mesh filename="package://my_robot_description/urdf/meshes/joint4_right_belt.stl" scale="0.001 0.001 0.001" />
            </geometry>
        </collision>
    </link>
    <link name="joint4_right_pulley1">
        <inertial>
            <origin xyz="-4.164622851021705e-09 -0.00032697486357173274 -0.016946000000000332" rpy="0.0 -0.0 0.0" />
            <mass value="0.01367927030145022" />
            <inertia ixx="1.2290355545104784e-06" iyy="1.2290355545143544e-06" izz="1.0454318700586773e-06" ixy="4.235164736271502e-22" iyz="7.411538288475128e-22" ixz="9.166099684884479e-40" />
        </inertial>
        <visual name="joint4_right_pulley1_visual">
            <origin xyz="-4.164622851021705e-09 -0.00032697486357173274 -0.016946000000000332" rpy="1.807539625230804e-17 -4.913746482809115e-16 3.141591994775655" />
            <geometry>
                <mesh filename="package://my_robot_description/urdf/meshes/joint4_right_pulley1.stl" scale="0.001 0.001 0.001" />
            </geometry>
        </visual>
        <collision name="joint4_right_pulley1_collision">
            <origin xyz="-4.164622851021705e-09 -0.00032697486357173274 -0.016946000000000332" rpy="1.807539625230804e-17 -4.913746482809115e-16 3.141591994775655" />
            <geometry>
                <mesh filename="package://my_robot_description/urdf/meshes/joint4_right_pulley1.stl" scale="0.001 0.001 0.001" />
            </geometry>
        </collision>
    </link>
    <link name="joint4_right_pulley2">
        <inertial>
            <origin xyz="-3.94923930002733e-09 -6.273848781824718e-10 -0.011749410474030811" rpy="0.0 -0.0 0.0" />
            <mass value="0.1436820712066979" />
            <inertia ixx="6.672582947984517e-05" iyy="6.672582947983563e-05" izz="0.000120543674556578" ixy="-3.4225425024994073e-19" iyz="3.181336635878944e-20" ixz="-1.734723475976807e-18" />
        </inertial>
        <visual name="joint4_right_pulley2_visual">
            <origin xyz="-3.94923930002733e-09 -6.273849256568389e-10 -0.01174941047403082" rpy="2.1930331947548616e-16 -1.2433924021263502e-16 3.141591994775655" />
            <geometry>
                <mesh filename="package://my_robot_description/urdf/meshes/joint4_right_pulley2.stl" scale="0.001 0.001 0.001" />
            </geometry>
        </visual>
        <collision name="joint4_right_pulley2_collision">
            <origin xyz="-3.94923930002733e-09 -6.273849256568389e-10 -0.01174941047403082" rpy="2.1930331947548616e-16 -1.2433924021263502e-16 3.141591994775655" />
            <geometry>
                <mesh filename="package://my_robot_description/urdf/meshes/joint4_right_pulley2.stl" scale="0.001 0.001 0.001" />
            </geometry>
        </collision>
    </link>
    <link name="joint4_frame">
        <inertial>
            <origin xyz="0.03316563606590847 -2.2477377437776152e-08 -4.330392262352797e-16" rpy="4.930380657631324e-32 -0.0 0.0" />
            <mass value="0.09195531537657577" />
            <inertia ixx="0.00039842933250533745" iyy="0.0003874187552594245" izz="0.00025847220907578006" ixy="-7.253924045234028e-12" iyz="7.52698497889397e-20" ixz="1.2850718768109691e-19" />
        </inertial>
        <visual name="joint4_frame_visual">
            <origin xyz="-3.949239442135877e-09 -6.273849256569744e-10 -4.214956148153978e-16" rpy="-1.5707969856090345 -1.5707963267948963 0" />
            <geometry>
                <mesh filename="package://my_robot_description/urdf/meshes/joint4_frame.stl" scale="0.001 0.001 0.001" />
            </geometry>
        </visual>
        <collision name="joint4_frame_collision">
            <origin xyz="-3.949239442135877e-09 -6.273849256569744e-10 -4.214956148153978e-16" rpy="-1.5707969856090345 -1.5707963267948963 0" />
            <geometry>
                <mesh filename="package://my_robot_description/urdf/meshes/joint4_frame.stl" scale="0.001 0.001 0.001" />
            </geometry>
        </collision>
    </link>
    <link name="mounting_plate">
        <inertial>
            <origin xyz="-5.006730168935328e-16 0.004999996050745494 -6.744375093540363e-09" rpy="0.0 -0.0 0.0" />
            <mass value="0.09416295660604687" />
            <inertia ixx="5.9684409839985686e-05" iyy="0.00011779943706992396" izz="5.968440984001344e-05" ixy="-4.4720379974826576e-20" iyz="-3.828700156420067e-11" ixz="6.777929423384796e-20" />
        </inertial>
        <visual name="mounting_plate_visual">
            <origin xyz="-4.965499089309793e-16 0.009999996050744357 -1.0038445790343173e-08" rpy="3.141591994775655 6.375591002035125e-19 4.880513931786541e-16" />
            <geometry>
                <mesh filename="package://my_robot_description/urdf/meshes/mounting_plate.stl" scale="0.001 0.001 0.001" />
            </geometry>
        </visual>
        <collision name="mounting_plate_collision">
            <origin xyz="-4.965499089309793e-16 0.009999996050744357 -1.0038445790343173e-08" rpy="3.141591994775655 6.375591002035125e-19 4.880513931786541e-16" />
            <geometry>
                <mesh filename="package://my_robot_description/urdf/meshes/mounting_plate.stl" scale="0.001 0.001 0.001" />
            </geometry>
        </collision>
    </link>
    <link name="Part5---ISO---Spur-Gear-1.125M-24T-20PA-3FW----S24A75H50L3.0N.ipt">
        <inertial>
            <origin xyz="0.0004623724911218741 -0.0014999970968359716 0.00528494667906088" rpy="0.0 -6.842277657836021e-49 5.574170058263222e-94" />
            <mass value="0.00256161383975765" />
            <inertia ixx="3.55679258809416e-07" iyy="4.4957631676906966e-07" izz="9.773947872066361e-08" ixy="-1.4982007565835294e-14" iyz="-2.3179508070174825e-13" ixz="-2.274087131531346e-08" />
        </inertial>
        <visual name="Part5---ISO---Spur-Gear-1.125M-24T-20PA-3FW----S24A75H50L3.0N.ipt_visual">
            <origin xyz="-1.432187701766452e-15 -0.003000000578629991 5.910418252597083e-09" rpy="0.08726646259969514 6.588141375219381e-07 1.5707963267948966" />
            <geometry>
                <mesh filename="package://my_robot_description/urdf/meshes/Part5---ISO---Spur-Gear-1.125M-24T-20PA-3FW----S24A75H50L3.0N.ipt.stl" scale="0.001 0.001 0.001" />
            </geometry>
        </visual>
        <collision name="Part5---ISO---Spur-Gear-1.125M-24T-20PA-3FW----S24A75H50L3.0N.ipt_collision">
            <origin xyz="-1.432187701766452e-15 -0.003000000578629991 5.910418252597083e-09" rpy="0.08726646259969514 6.588141375219381e-07 1.5707963267948966" />
            <geometry>
                <mesh filename="package://my_robot_description/urdf/meshes/Part5---ISO---Spur-Gear-1.125M-24T-20PA-3FW----S24A75H50L3.0N.ipt.stl" scale="0.001 0.001 0.001" />
            </geometry>
        </collision>
    </link>
    <link name="Part5-1---ISO---Spur-Gear-1.125M-24T-20PA-3FW----S24A75H50L3.0N.ipt">
        <inertial>
            <origin xyz="8.721576702164002e-05 -0.0014999967492662469 0.005812515614097862" rpy="0.0 -6.842277657836021e-49 5.574170058263222e-94" />
            <mass value="0.0023526459288513656" />
            <inertia ixx="3.325699773405223e-07" iyy="4.1174468567561233e-07" izz="8.270367722848829e-08" ixy="1.983301120629806e-14" iyz="-2.1677686975660724e-13" ixz="3.0104107968500556e-08" />
        </inertial>
        <visual name="Part5-1---ISO---Spur-Gear-1.125M-24T-20PA-3FW----S24A75H50L3.0N.ipt_visual">
            <origin xyz="-1.2989609388114333e-15 -5.786307838429039e-10 3.9339744262179014e-09" rpy="0.21816615649931234 -6.588141373970379e-07 -1.570796326794897" />
            <geometry>
                <mesh filename="package://my_robot_description/urdf/meshes/Part5-1---ISO---Spur-Gear-1.125M-24T-20PA-3FW----S24A75H50L3.0N.ipt.stl" scale="0.001 0.001 0.001" />
            </geometry>
        </visual>
        <collision name="Part5-1---ISO---Spur-Gear-1.125M-24T-20PA-3FW----S24A75H50L3.0N.ipt_collision">
            <origin xyz="-1.2989609388114333e-15 -5.786307838429039e-10 3.9339744262179014e-09" rpy="0.21816615649931234 -6.588141373970379e-07 -1.570796326794897" />
            <geometry>
                <mesh filename="package://my_robot_description/urdf/meshes/Part5-1---ISO---Spur-Gear-1.125M-24T-20PA-3FW----S24A75H50L3.0N.ipt.stl" scale="0.001 0.001 0.001" />
            </geometry>
        </collision>
    </link>
    <link name="Part8---ISO---Spur-gear-1M-13T-20PA-10FW----S13A75H50L0.8N.ipt">
        <inertial>
            <origin xyz="-9.259260025373805e-16 -0.002611338164874612 6.2627634633827254e-09" rpy="0.0 -0.0 9.896373449434974e-95" />
            <mass value="0.0023562783298226395" />
            <inertia ixx="6.890586734574836e-08" iyy="6.539312475285078e-08" izz="6.890586734577236e-08" ixy="5.59174094085846e-22" iyz="2.3142444661260038e-15" ixz="-1.0164395367051603e-20" />
        </inertial>
        <visual name="Part8---ISO---Spur-gear-1M-13T-20PA-10FW----S13A75H50L0.8N.ipt_visual">
            <origin xyz="-1.0125233984581429e-15 -3.1698581071104572e-09 4.5423790595577886e-09" rpy="-1.8151424220740815 -6.588141384101162e-07 -1.570796326794905" />
            <geometry>
                <mesh filename="package://my_robot_description/urdf/meshes/Part8---ISO---Spur-gear-1M-13T-20PA-10FW----S13A75H50L0.8N.ipt.stl" scale="0.001 0.001 0.001" />
            </geometry>
        </visual>
        <collision name="Part8---ISO---Spur-gear-1M-13T-20PA-10FW----S13A75H50L0.8N.ipt_collision">
            <origin xyz="-1.0125233984581429e-15 -3.1698581071104572e-09 4.5423790595577886e-09" rpy="-1.8151424220740815 -6.588141384101162e-07 -1.570796326794905" />
            <geometry>
                <mesh filename="package://my_robot_description/urdf/meshes/Part8---ISO---Spur-gear-1M-13T-20PA-10FW----S13A75H50L0.8N.ipt.stl" scale="0.001 0.001 0.001" />
            </geometry>
        </collision>
    </link>
    <link name="Part1_1">
        <inertial>
            <origin xyz="0.02349130079337655 0.001500015243293029 0.005244104776289396" rpy="0.0 -0.0 0.0" />
            <mass value="0.0017624611608733033" />
            <inertia ixx="2.7235688656142942e-08" iyy="5.640552446775293e-07" izz="5.394632477629879e-07" ixy="-3.5366431345325416e-13" iyz="-4.810639495259831e-14" ixz="-7.301967586047654e-08" />
        </inertial>
        <visual name="Part1_1_visual">
            <origin xyz="-4.251866414506367e-10 -2.331086462747933e-10 1.9748247814810328e-09" rpy="-1.5707963267948966 -0.3839140524349979 6.588141374063894e-07" />
            <geometry>
                <mesh filename="package://my_robot_description/urdf/meshes/Part1_1.stl" scale="0.001 0.001 0.001" />
            </geometry>
        </visual>
        <collision name="Part1_1_collision">
            <origin xyz="-4.251866414506367e-10 -2.331086462747933e-10 1.9748247814810328e-09" rpy="-1.5707963267948966 -0.3839140524349979 6.588141374063894e-07" />
            <geometry>
                <mesh filename="package://my_robot_description/urdf/meshes/Part1_1.stl" scale="0.001 0.001 0.001" />
            </geometry>
        </collision>
    </link>
    <link name="Part1_2">
        <inertial>
            <origin xyz="-0.005244104776289513 -0.0015000152432924076 -0.023491298816934007" rpy="0.0 -0.0 0.0" />
            <mass value="0.0017624611608733033" />
            <inertia ixx="5.394632477634213e-07" iyy="5.64055244677529e-07" izz="2.723568865613903e-08" ixy="-4.8106394612888506e-14" iyz="-3.536643121785522e-13" ixz="-7.301967586046972e-08" />
        </inertial>
        <visual name="Part1_2_visual">
            <origin xyz="-1.9748249968642997e-09 2.331092607040907e-10 2.4016289046358e-09" rpy="-1.5707945678580164 1.1868822743593619 -3.14159102269345" />
            <geometry>
                <mesh filename="package://my_robot_description/urdf/meshes/Part1_2.stl" scale="0.001 0.001 0.001" />
            </geometry>
        </visual>
        <collision name="Part1_2_collision">
            <origin xyz="-1.9748249968642997e-09 2.331092607040907e-10 2.4016289046358e-09" rpy="-1.5707945678580164 1.1868822743593619 -3.14159102269345" />
            <geometry>
                <mesh filename="package://my_robot_description/urdf/meshes/Part1_2.stl" scale="0.001 0.001 0.001" />
            </geometry>
        </collision>
    </link>
    <link name="Part1_3">
        <inertial>
            <origin xyz="0.023491300793374706 0.001500015243292552 -0.005244104776284548" rpy="2.93873587705572e-39 -0.0 0.0" />
            <mass value="0.0017624611608733033" />
            <inertia ixx="2.7235688656140056e-08" iyy="5.640552446779629e-07" izz="5.394632477638552e-07" ixy="-3.536643126144271e-13" iyz="4.810639507069896e-14" ixz="7.301967586046299e-08" />
        </inertial>
        <visual name="Part1_3_visual">
            <origin xyz="-2.40163089415546e-09 0.0029999997668902234 -1.9748204338476683e-09" rpy="1.5707963267948961 0.38391405243497795 6.588141373304609e-07" />
            <geometry>
                <mesh filename="package://my_robot_description/urdf/meshes/Part1_3.stl" scale="0.001 0.001 0.001" />
            </geometry>
        </visual>
        <collision name="Part1_3_collision">
            <origin xyz="-2.40163089415546e-09 0.0029999997668902234 -1.9748204338476683e-09" rpy="1.5707963267948961 0.38391405243497795 6.588141373304609e-07" />
            <geometry>
                <mesh filename="package://my_robot_description/urdf/meshes/Part1_3.stl" scale="0.001 0.001 0.001" />
            </geometry>
        </collision>
    </link>
    <link name="Part1_4">
        <inertial>
            <origin xyz="0.005244104776284653 0.0015000152432923842 0.02349129881693344" rpy="-5.877471754111438e-39 -0.0 6.22301527786114e-61" />
            <mass value="0.0017624611608733033" />
            <inertia ixx="5.39463247762554e-07" iyy="5.640552446770954e-07" izz="2.7235688656139395e-08" ixy="-4.8106393559274345e-14" iyz="-3.5366431217044546e-13" ixz="-7.301967586047314e-08" />
        </inertial>
        <visual name="Part1_4_visual">
            <origin xyz="1.974820504901942e-09 0.0029999997668900542 -4.37807230468934e-09" rpy="1.5707945678580162 -1.1868822743593814 1.6308963432191163e-06" />
            <geometry>
                <mesh filename="package://my_robot_description/urdf/meshes/Part1_4.stl" scale="0.001 0.001 0.001" />
            </geometry>
        </visual>
        <collision name="Part1_4_collision">
            <origin xyz="1.974820504901942e-09 0.0029999997668900542 -4.37807230468934e-09" rpy="1.5707945678580162 -1.1868822743593814 1.6308963432191163e-06" />
            <geometry>
                <mesh filename="package://my_robot_description/urdf/meshes/Part1_4.stl" scale="0.001 0.001 0.001" />
            </geometry>
        </collision>
    </link>
    <link name="Part2_1">
        <inertial>
            <origin xyz="0.001360929242553235 -0.0014999869664528065 0.015440137749320116" rpy="0.0 -6.842277657836021e-49 5.574170058263222e-94" />
            <mass value="0.0004909736411079125" />
            <inertia ixx="6.827553504431139e-08" iyy="6.945397387390312e-08" izz="1.91210690828219e-09" ixy="-3.883844336699436e-15" iyz="-4.449753714843156e-14" ixz="-5.8952049060950605e-09" />
        </inertial>
        <visual name="Part2_1_visual">
            <origin xyz="4.601907355183954e-09 -0.001499997138634489 -9.84605890153034e-10" rpy="-1.570803830236917 -1.4828815317581812 7.4744635954201e-06" />
            <geometry>
                <mesh filename="package://my_robot_description/urdf/meshes/Part2_1.stl" scale="0.001 0.001 0.001" />
            </geometry>
        </visual>
        <collision name="Part2_1_collision">
            <origin xyz="4.601907355183954e-09 -0.001499997138634489 -9.84605890153034e-10" rpy="-1.570803830236917 -1.4828815317581812 7.4744635954201e-06" />
            <geometry>
                <mesh filename="package://my_robot_description/urdf/meshes/Part2_1.stl" scale="0.001 0.001 0.001" />
            </geometry>
        </collision>
    </link>
    <link name="Part2_2">
        <inertial>
            <origin xyz="0.001350914012588349 -0.0015000095941285969 -0.01544101681330389" rpy="0.0 -0.0 -9.896373449434974e-95" />
            <mass value="0.0004909736411079125" />
            <inertia ixx="6.828315125221446e-08" iyy="6.945397387368623e-08" izz="1.9044907001903145e-09" ixy="3.85549523417888e-15" iyz="-4.450255412457811e-14" ixz="5.85217439929955e-09" />
        </inertial>
        <visual name="Part2_2_visual">
            <origin xyz="-1.4477308241112042e-15 -0.0014999994213677592 1.0071310896364594e-09" rpy="-1.5708038858393927 1.4835298641927201 -7.5302800492952e-06" />
            <geometry>
                <mesh filename="package://my_robot_description/urdf/meshes/Part2_2.stl" scale="0.001 0.001 0.001" />
            </geometry>
        </visual>
        <collision name="Part2_2_collision">
            <origin xyz="-1.4477308241112042e-15 -0.0014999994213677592 1.0071310896364594e-09" rpy="-1.5708038858393927 1.4835298641927201 -7.5302800492952e-06" />
            <geometry>
                <mesh filename="package://my_robot_description/urdf/meshes/Part2_2.stl" scale="0.001 0.001 0.001" />
            </geometry>
        </collision>
    </link>
    <link name="Part2_3">
        <inertial>
            <origin xyz="0.0013609292425532538 -0.0015000130335449213 -0.01544014181999259" rpy="0.0 -0.0 -9.896373449434974e-95" />
            <mass value="0.0004909736411079125" />
            <inertia ixx="6.827553504420297e-08" iyy="6.945397387368623e-08" izz="1.912106908282195e-09" ixy="3.8838443400081565e-15" iyz="-4.4497536724915047e-14" ixz="5.895204906095058e-09" />
        </inertial>
        <visual name="Part2_3_visual">
            <origin xyz="4.601907356294177e-09 -0.0015000028613632406 -3.086066584501168e-09" rpy="-1.5708038302369138 1.4828815317581794 -7.474463594155496e-06" />
            <geometry>
                <mesh filename="package://my_robot_description/urdf/meshes/Part2_3.stl" scale="0.001 0.001 0.001" />
            </geometry>
        </visual>
        <collision name="Part2_3_collision">
            <origin xyz="4.601907356294177e-09 -0.0015000028613632406 -3.086066584501168e-09" rpy="-1.5708038302369138 1.4828815317581794 -7.474463594155496e-06" />
            <geometry>
                <mesh filename="package://my_robot_description/urdf/meshes/Part2_3.stl" scale="0.001 0.001 0.001" />
            </geometry>
        </collision>
    </link>
    <link name="Part2_4">
        <inertial>
            <origin xyz="-0.0013609292425546039 -0.0014999869664527488 0.015440137749286863" rpy="0.0 -6.842277657836021e-49 5.574170058263222e-94" />
            <mass value="0.0004909736411079125" />
            <inertia ixx="6.827553504398613e-08" iyy="6.945397387357786e-08" izz="1.9121069082827458e-09" ixy="3.883844520333532e-15" iyz="-4.449753714843156e-14" ixz="5.895204906098449e-09" />
        </inertial>
        <visual name="Part2_4_visual">
            <origin xyz="-0.002721853883201252 -0.0014999767942710863 0.030880276483212583" rpy="1.5707888233528804 1.48288153175813 -7.474463580400319e-06" />
            <geometry>
                <mesh filename="package://my_robot_description/urdf/meshes/Part2_4.stl" scale="0.001 0.001 0.001" />
            </geometry>
        </visual>
        <collision name="Part2_4_collision">
            <origin xyz="-0.002721853883201252 -0.0014999767942710863 0.030880276483212583" rpy="1.5707888233528804 1.48288153175813 -7.474463580400319e-06" />
            <geometry>
                <mesh filename="package://my_robot_description/urdf/meshes/Part2_4.stl" scale="0.001 0.001 0.001" />
            </geometry>
        </collision>
    </link>
    <link name="Part2_5">
        <inertial>
            <origin xyz="-0.0013509140125890795 -0.0015000095941285435 -0.015441016813271488" rpy="0.0 -0.0 -9.896373449434974e-95" />
            <mass value="0.0004909736411079125" />
            <inertia ixx="6.828315125221446e-08" iyy="6.945397387346939e-08" izz="1.904490700190738e-09" ixy="-3.855495419467337e-15" iyz="-4.450255412457811e-14" ixz="-5.8521743993046325e-09" />
        </inertial>
        <visual name="Part2_5_visual">
            <origin xyz="-0.0027018280251795445 -0.0015000197668893645 -0.030882034633706326" rpy="-1.5708038858393925 -1.4835298641926769 7.530280037190053e-06" />
            <geometry>
                <mesh filename="package://my_robot_description/urdf/meshes/Part2_5.stl" scale="0.001 0.001 0.001" />
            </geometry>
        </visual>
        <collision name="Part2_5_collision">
            <origin xyz="-0.0027018280251795445 -0.0015000197668893645 -0.030882034633706326" rpy="-1.5708038858393925 -1.4835298641926769 7.530280037190053e-06" />
            <geometry>
                <mesh filename="package://my_robot_description/urdf/meshes/Part2_5.stl" scale="0.001 0.001 0.001" />
            </geometry>
        </collision>
    </link>
    <link name="Part2_6">
        <inertial>
            <origin xyz="-0.0013609292425544196 -0.001500013033545084 -0.015440141819960332" rpy="0.0 -0.0 -9.896373449434974e-95" />
            <mass value="0.0004909736411079125" />
            <inertia ixx="6.827553504420297e-08" iyy="6.945397387368623e-08" izz="1.9121069082825787e-09" ixy="-3.8838445236422524e-15" iyz="-4.449753630139857e-14" ixz="-5.8952049060971756e-09" />
        </inertial>
        <visual name="Part2_6_visual">
            <origin xyz="-0.0027218538832009475 -0.00150002320572675 -0.030880280553886197" rpy="-1.5708038302369127 -1.4828815317581383 7.474463582929915e-06" />
            <geometry>
                <mesh filename="package://my_robot_description/urdf/meshes/Part2_6.stl" scale="0.001 0.001 0.001" />
            </geometry>
        </visual>
        <collision name="Part2_6_collision">
            <origin xyz="-0.0027218538832009475 -0.00150002320572675 -0.030880280553886197" rpy="-1.5708038302369127 -1.4828815317581383 7.474463582929915e-06" />
            <geometry>
                <mesh filename="package://my_robot_description/urdf/meshes/Part2_6.stl" scale="0.001 0.001 0.001" />
            </geometry>
        </collision>
    </link>
    <link name="Part3_1">
        <inertial>
            <origin xyz="0.005535888524214898 -0.027093128195806032 0.001500015134865492" rpy="0.0 -0.0 0.0" />
            <mass value="0.0051126604483966425" />
            <inertia ixx="1.6745237188435869e-06" iyy="7.659415972045138e-07" izz="2.4328103187566683e-06" ixy="4.540360567495301e-08" iyz="1.0974291035654324e-12" ixz="-2.8406565927919935e-14" />
        </inertial>
        <visual name="Part3_1_visual">
            <origin xyz="0.005999999999999346 0.004000003949257405 0.002999994650144417" rpy="3.141591994775655 1.0099650530420098e-16 -2.1304739762049893e-14" />
            <geometry>
                <mesh filename="package://my_robot_description/urdf/meshes/Part3_1.stl" scale="0.001 0.001 0.001" />
            </geometry>
        </visual>
        <collision name="Part3_1_collision">
            <origin xyz="0.005999999999999346 0.004000003949257405 0.002999994650144417" rpy="3.141591994775655 1.0099650530420098e-16 -2.1304739762049893e-14" />
            <geometry>
                <mesh filename="package://my_robot_description/urdf/meshes/Part3_1.stl" scale="0.001 0.001 0.001" />
            </geometry>
        </collision>
    </link>
    <link name="Part3_2">
        <inertial>
            <origin xyz="-0.006464111475785103 -0.0015000151348648749 -0.02709312621936391" rpy="0.0 6.842277657836021e-49 -5.574170058263222e-94" />
            <mass value="0.0051126604483966425" />
            <inertia ixx="1.6745237188427187e-06" iyy="2.432810318755801e-06" izz="7.659415972045155e-07" ixy="2.8406565276227682e-14" iyz="-1.0974291052588468e-12" ixz="4.540360567495385e-08" />
        </inertial>
        <visual name="Part3_2_visual">
            <origin xyz="-0.006000000000000652 -0.0029999946501438036 0.004000005925699668" rpy="-1.570796985609034 2.130471942664171e-14 7.324092971439662e-17" />
            <geometry>
                <mesh filename="package://my_robot_description/urdf/meshes/Part3_2.stl" scale="0.001 0.001 0.001" />
            </geometry>
        </visual>
        <collision name="Part3_2_collision">
            <origin xyz="-0.006000000000000652 -0.0029999946501438036 0.004000005925699668" rpy="-1.570796985609034 2.130471942664171e-14 7.324092971439662e-17" />
            <geometry>
                <mesh filename="package://my_robot_description/urdf/meshes/Part3_2.stl" scale="0.001 0.001 0.001" />
            </geometry>
        </collision>
    </link>
    <link name="Part7_1">
        <inertial>
            <origin xyz="9.489131426425495e-17 0.004734091075852121 -0.0050986038896102485" rpy="0.0 -0.0 0.0" />
            <mass value="0.0009632349420271968" />
            <inertia ixx="2.4532632541748867e-08" iyy="3.864568085778191e-08" izz="4.816143162533411e-08" ixy="2.164674035567733e-21" iyz="6.834760224165121e-09" ixz="-3.559916741286855e-21" />
        </inertial>
        <visual name="Part7_1_visual">
            <origin xyz="-5.374821888555481e-16 0.0019999993448142563 -0.00600000135607446" rpy="1.5707963267948968 -6.588141375219381e-07 -1.570796326794875" />
            <geometry>
                <mesh filename="package://my_robot_description/urdf/meshes/Part7_1.stl" scale="0.001 0.001 0.001" />
            </geometry>
        </visual>
        <collision name="Part7_1_collision">
            <origin xyz="-5.374821888555481e-16 0.0019999993448142563 -0.00600000135607446" rpy="1.5707963267948968 -6.588141375219381e-07 -1.570796326794875" />
            <geometry>
                <mesh filename="package://my_robot_description/urdf/meshes/Part7_1.stl" scale="0.001 0.001 0.001" />
            </geometry>
        </collision>
    </link>
    <link name="Part7_2">
        <inertial>
            <origin xyz="0.0059999999999986835 -0.0029013924250526307 0.006265906699998567" rpy="0.0 -0.0 -9.896373449434974e-95" />
            <mass value="0.0009632349420271968" />
            <inertia ixx="2.4532632541532026e-08" iyy="4.81614496361006e-08" izz="3.864566284645178e-08" ixy="-3.2673481824359515e-21" iyz="6.834747685918415e-09" ixz="2.7751230259084284e-21" />
        </inertial>
        <visual name="Part7_2_visual">
            <origin xyz="0.005999999999999433 -0.0019999913560726297 0.008999997243327158" rpy="-3.141592653589793 -1.570795667980759 0" />
            <geometry>
                <mesh filename="package://my_robot_description/urdf/meshes/Part7_2.stl" scale="0.001 0.001 0.001" />
            </geometry>
        </visual>
        <collision name="Part7_2_collision">
            <origin xyz="0.005999999999999433 -0.0019999913560726297 0.008999997243327158" rpy="-3.141592653589793 -1.570795667980759 0" />
            <geometry>
                <mesh filename="package://my_robot_description/urdf/meshes/Part7_2.stl" scale="0.001 0.001 0.001" />
            </geometry>
        </collision>
    </link>
    <joint name="joint1_base_joint1_in" type="fixed">
        <origin xyz="-5.52736357277545e-18 -0.15000000310694728 0.022499995126911223" rpy="-3.141591994775654 -2.4380995954270237e-17 -7.577232939035826e-18" />
        <parent link="joint1_base" />
        <child link="joint1_reducer_pulley1" />
    </joint>
    <joint name="joint1_base_base_belt" type="fixed">
        <origin xyz="-7.366776133681121e-19 -3.106920669546901e-09 0.02250000394903208" rpy="-3.141591994775654 -2.4380995954270237e-17 -7.577232939035826e-18" />
        <parent link="joint1_base" />
        <child link="joint1_reducer_belt" />
    </joint>
    <joint name="joint1_base_joint1" type="revolute">
        <origin xyz="-1.2741636791780136e-18 -4.636168103382642e-09 0.04000000394903485" rpy="-3.141591994775654 -2.4380995954270237e-17 -7.577232939035827e-18" />
        <parent link="joint1_base" />
        <child link="joint2_base" />
        <axis xyz="-3.081488310952143e-33 1.0000000002220446e-06 1.0" />
        <limit lower="-3.141593" upper="3.141593" effort="1000000" velocity="1000000" />
    </joint>
    <joint name="joint2_base_joint1_gear" type="fixed">
        <origin xyz="0.0 0.0 0.0" rpy="1.5707963267948963 -4.124433518843144e-33 3.999325655085137e-34" />
        <parent link="joint2_base" />
        <child link="joint1_reducer_pulley2" />
    </joint>
    <joint name="joint2_base_joint2" type="revolute">
        <origin xyz="6.62196875021603e-40 -1.4000000004551903e-07 -0.20500000000000002" rpy="-3.141592653589793 1.5707963267948963 0" />
        <parent link="joint2_base" />
        <child link="joint2_frame" />
        <axis xyz="-1.3739031035617033e-33 2.422304781000339e-16 0.9999999999999996" />
        <limit lower="-1.570796" upper="1.570796" effort="1000000" velocity="1000000" />
    </joint>
    <joint name="joint2_frame_joint2_gear" type="fixed">
        <origin xyz="-3.552713678800501e-17 -1.6855820125089016e-17 -0.060000000000000026" rpy="-2.422304781000341e-16 -1.525955435103023e-33 -1.0587911840678766e-22" />
        <parent link="joint2_frame" />
        <child link="joint2_reducer_pulley2" />
    </joint>
    <joint name="joint2_base_joint2_in" type="fixed">
        <origin xyz="0.055 -4.000000001110212e-08 -0.05000000000000001" rpy="3.141592653589793 1.5707963267948963 0" />
        <parent link="joint2_base" />
        <child link="joint2_reducer_pulley1" />
    </joint>
    <joint name="joint2_base_joint2_belt" type="fixed">
        <origin xyz="0.055 -4.000000001110212e-08 -0.05000000000000001" rpy="3.141592653589793 1.5707963267948963 0" />
        <parent link="joint2_base" />
        <child link="joint2_reducer_belt" />
    </joint>
    <joint name="joint2_frame_joint2_linkB" type="fixed">
        <origin xyz="0.06500000000000007 4.000000000000016e-08 -9.689219123912101e-24" rpy="1.570796326794897 1.5707963267948963 0" />
        <parent link="joint2_frame" />
        <child link="Link_B" />
    </joint>
    <joint name="Link_B_linkB_joint3" type="fixed">
        <origin xyz="1.444253501722542e-35 0.095 -7.000000003835292e-08" rpy="-1.570796326794897 1.2332440372894848e-32 4.509548978059492e-34" />
        <parent link="Link_B" />
        <child link="joint3_base" />
    </joint>
    <joint name="joint3_base_joint3_y" type="revolute">
        <origin xyz="2.0214560732609322e-32 1.3000000000000005e-07 0.20500000000000002" rpy="3.141592653589793 -1.5707963267948966 0" />
        <parent link="joint3_base" />
        <child link="joint3_frame" />
        <axis xyz="3.4302805947955624e-33 -2.4223047810003335e-16 0.9999999999999993" />
        <limit lower="-1.570796" upper="1.570796" effort="1000000" velocity="1000000" />
    </joint>
    <joint name="joint3_frame_joint3_left_miter_gear" type="fixed">
        <origin xyz="-7.105427357601002e-17 -1.1576297646170853e-17 0.055000000000000035" rpy="-3.141592653589793 3.3328299758499414e-33 1.0587911840678775e-22" />
        <parent link="joint3_frame" />
        <child link="joint3_miter_gear_left" />
    </joint>
    <joint name="joint3_frame_joint3_left_pulley2" type="fixed">
        <origin xyz="-7.105427357601002e-17 -1.2628651379839596e-17 0.06000000000000004" rpy="-3.141592653589793 3.3328299758499414e-33 1.0587911840678775e-22" />
        <parent link="joint3_frame" />
        <child link="joint3_left_pulley2" />
    </joint>
    <joint name="joint3_base_joint3_left_in" type="fixed">
        <origin xyz="0.055 3.000000000000005e-08 0.05" rpy="-6.488728816539028e-36 -1.5707963267948966 0" />
        <parent link="joint3_base" />
        <child link="joint3_left_pulley1" />
    </joint>
    <joint name="joint3_base_joint3_left_belt" type="fixed">
        <origin xyz="0.055 3.000000000000005e-08 0.05" rpy="-6.488728816539028e-36 -1.5707963267948966 0" />
        <parent link="joint3_base" />
        <child link="joint3_left_belt" />
    </joint>
    <joint name="joint3_frame_joint3_right_miter_gear" type="fixed">
        <origin xyz="-7.105427357601002e-17 1.157602659562773e-17 -0.055000000000000035" rpy="3.966962902217947e-16 3.3328299758499414e-33 1.0587911840678775e-22" />
        <parent link="joint3_frame" />
        <child link="joint3_miter_gear_right" />
    </joint>
    <joint name="joint3_frame_joint3_right_pulley2" type="fixed">
        <origin xyz="-7.105427357601002e-17 1.2628380329296474e-17 -0.06000000000000004" rpy="2.4223047810003384e-16 3.3328299758499414e-33 1.0587911840678775e-22" />
        <parent link="joint3_frame" />
        <child link="joint3_right_pulley2" />
    </joint>
    <joint name="joint3_base_joint3_right_in" type="fixed">
        <origin xyz="-0.055 3.000000000000005e-08 0.05" rpy="3.141592653589793 -1.5707963267948966 0" />
        <parent link="joint3_base" />
        <child link="joint3_right_pulley1" />
    </joint>
    <joint name="joint3_base_joint3_right_belt" type="fixed">
        <origin xyz="-0.055 3.000000000000005e-08 0.05" rpy="3.141592653589793 -1.5707963267948966 0" />
        <parent link="joint3_base" />
        <child link="joint3_right_belt" />
    </joint>
    <joint name="joint3_frame_joint3_z" type="continuous">
        <origin xyz="0.06500000000000007 -4.000000000000003e-08 -9.689219124224342e-24" rpy="-1.5707963267948961 -1.5707963267948963 0" />
        <parent link="joint3_frame" />
        <child link="Link_A" />
        <axis xyz="-3.5894438690200686e-34 -0.9999999999999999 1.0000000004037172e-06" />
    </joint>
    <joint name="Link_A_joint3_center_miter_gear" type="fixed">
        <origin xyz="0.0 0.0 -1.3552527156068806e-22" rpy="1.5707963267948961 9.860770719217454e-32 -3.5904299451519935e-34" />
        <parent link="Link_A" />
        <child link="joint3_miter_gear_center" />
    </joint>
    <joint name="Link_A_linkA_joint4" type="fixed">
        <origin xyz="-9.255372320634363e-36 0.095 -7.000000003835333e-08" rpy="-1.570796326794897 9.860770719217454e-32 -3.5904299451519935e-34" />
        <parent link="Link_A" />
        <child link="joint4_base" />
    </joint>
    <joint name="joint4_base_joint4_y" type="revolute">
        <origin xyz="-1.2414630937904348e-41 1.3000000000000005e-07 0.20500000000000002" rpy="3.141592653589793 -1.5707963267948966 0" />
        <parent link="joint4_base" />
        <child link="joint4_frame" />
        <axis xyz="2.8212334617475222e-33 -2.42230478100034e-16 0.9999999999999998" />
        <limit lower="-1.570796" upper="1.570796" effort="1000000" velocity="1000000" />
    </joint>
    <joint name="joint4_frame_joint4_left_miter_gear" type="fixed">
        <origin xyz="-1.4210854715202004e-16 -1.1576568696713974e-17 0.05500000000000001" rpy="-3.141592653589793 -1.251338421831691e-32 -2.633832531931753e-48" />
        <parent link="joint4_frame" />
        <child link="joint4_miter_gear_left" />
    </joint>
    <joint name="joint4_frame_joint4_left_pulley2" type="fixed">
        <origin xyz="-1.4210854715202004e-16 -1.2629057955654277e-17 0.06000000000000002" rpy="-3.141592653589793 -1.251338421831691e-32 -2.633832531931753e-48" />
        <parent link="joint4_frame" />
        <child link="joint4_left_pulley2" />
    </joint>
    <joint name="joint4_base_joint4_left_in" type="fixed">
        <origin xyz="0.055 3.000000000000005e-08 0.05" rpy="-9.4039548065783e-38 -1.5707963267948966 0" />
        <parent link="joint4_base" />
        <child link="joint4_left_pulley1" />
    </joint>
    <joint name="joint4_base_joint4_left_belt" type="fixed">
        <origin xyz="0.055 3.000000000000005e-08 0.05" rpy="-9.4039548065783e-38 -1.5707963267948966 0" />
        <parent link="joint4_base" />
        <child link="joint4_left_belt" />
    </joint>
    <joint name="joint4_frame_joint4_right_miter_gear" type="fixed">
        <origin xyz="-1.4210854715202004e-16 1.1576297646170853e-17 -0.05500000000000001" rpy="3.96696290221795e-16 -1.251338421831691e-32 -2.633832531931753e-48" />
        <parent link="joint4_frame" />
        <child link="joint4_miter_gear_right" />
    </joint>
    <joint name="joint4_frame_joint4_right_pulley2" type="fixed">
        <origin xyz="-1.4210854715202004e-16 1.2628786905111156e-17 -0.06000000000000002" rpy="2.4223047810003414e-16 -1.251338421831691e-32 -2.633832531931753e-48" />
        <parent link="joint4_frame" />
        <child link="joint4_right_pulley2" />
    </joint>
    <joint name="joint4_base_joint4_right_in" type="fixed">
        <origin xyz="-0.055 3.000000000000005e-08 0.05" rpy="3.141592653589793 -1.5707963267948966 0" />
        <parent link="joint4_base" />
        <child link="joint4_right_pulley1" />
    </joint>
    <joint name="joint4_base_joint4_right_belt" type="fixed">
        <origin xyz="-0.055 3.000000000000005e-08 0.05" rpy="3.141592653589793 -1.5707963267948966 0" />
        <parent link="joint4_base" />
        <child link="joint4_right_belt" />
    </joint>
    <joint name="joint4_frame_joint4_z" type="continuous">
        <origin xyz="0.06499999999999986 -4.000000000000016e-08 -9.689219124184741e-24" rpy="-1.5707963267948961 -1.5707963267948963 0" />
        <parent link="joint4_frame" />
        <child link="mounting_plate" />
        <axis xyz="-4.698010109855125e-35 -1.0 1.0000000004037175e-06" />
    </joint>
    <joint name="mounting_plate_joint4_center_miter_gear" type="fixed">
        <origin xyz="0.0 0.0 0.0" rpy="3.1415926535897927 -3.863276849803671e-50 -9.569258699662684e-35" />
        <parent link="mounting_plate" />
        <child link="joint4_miter_gear_center" />
    </joint>

    <joint name="Part3_1_gripper_base" type="fixed">
        <origin xyz="0.011999999999999997 0.0 0.0029999999999999988" rpy="-1.5707963267948966 3.1554436208840472e-30 -3.150646851616307e-30" />
        <parent link="Part3_1" />
        <child link="Part3_2" />
    </joint>
    <joint name="Part3_1_gripper_joint" type="revolute">
        <origin xyz="0.019499999999999997 -0.03359971000000002 1.999999999946489e-08" rpy="1.5707963267948966 3.1554436208840472e-30 -3.150646851616307e-30" />
        <parent link="Part3_1" />
        <child link="Part5---ISO---Spur-Gear-1.125M-24T-20PA-3FW----S24A75H50L3.0N.ipt" />
        <axis xyz="3.155443616087278e-30 -1.0000000000000002 1.0000000000000002e-06" />
        <limit lower="-1.570796" upper="0.0" effort="1000000" velocity="1000000" />
    </joint>
    <joint name="Part3_1_gripper_joint_right1" type="continuous">
        <origin xyz="0.011239819999999996 -0.053999999999999916 2.9999999999752445e-08" rpy="1.5707963267948966 3.1554436208840472e-30 -3.150646851616307e-30" />
        <parent link="Part3_1" />
        <child link="Part2_1" />
        <axis xyz="3.155443616087278e-30 -1.0000000000000002 1.0000000000000002e-06" />
        <mimic joint="Part3_1_gripper_joint" multiplier="1.0" offset="0.0"/>
    </joint>
    <joint name="Part5---ISO---Spur-Gear-1.125M-24T-20PA-3FW----S24A75H50L3.0N.ipt_gripper_joint_right2" type="continuous">
        <origin xyz="0.0027018299999999984 2.000000000002e-08 0.030882039999999764" rpy="6.617448055867841e-24 -1.5707963267948966 0" />
        <parent link="Part5---ISO---Spur-Gear-1.125M-24T-20PA-3FW----S24A75H50L3.0N.ipt" />
        <child link="Part1_1" />
        <axis xyz="1.000000000013878e-06 -1.0000000000000002 6.617550779542628e-24" />
        <mimic joint="Part3_1_gripper_joint" multiplier="-1.0" offset="0.0"/>
    </joint>
    <!-- <joint name="Part2_1_gripper_joint_right3" type="continuous">
        <origin xyz="0.00272185 2.000000000002e-08 0.030880279999999944" rpy="3.141592653589793 1.0587911840199075e-22 3.1554436208840465e-30" />
        <parent link="Part2_1" />
        <child link="Part1_1" />
        <axis xyz="-1.0587911840678754e-28 1.0 -1e-06" />
    </joint> -->
    <joint name="Part1_1_gripper_joint_right4" type="fixed">
        <origin xyz="-1.4210854715202004e-16 0.002999999999999999 0.0" rpy="3.141592653589793 1.5707963267948966 0" />
        <parent link="Part1_1" />
        <child link="Part1_2" />
    </joint>
    <joint name="Part3_2_gripper_joint_right5" type="continuous">
        <origin xyz="0.0075000000000000015 -0.00300002 -0.03359970999999987" rpy="-1.0587911840678752e-22 8.431962037770366e-33 4.224339667742767e-94" />
        <parent link="Part3_2" />
        <child link="Part2_2" />
        <axis xyz="-3.1554436245192396e-30 -0.9999999999999999 9.999999999999997e-07" />
        <mimic joint="Part3_1_gripper_joint" multiplier="-1.0" offset="0.0"/>
    </joint>
    <!-- <joint name="Part1_2_gripper_joint_right6" type="continuous">
        <origin xyz="-2.220446049250313e-18 -0.003 0.0" rpy="-5.293955920339378e-23 -0.0 -1.1102230246251565e-16" />
        <parent link="Part1_2" />
        <child link="Part2_2" />
        <axis xyz="0.0 1.0 -9.999999999999997e-07" />
    </joint> -->
    <joint name="Part3_2_gripper_joint_right7" type="continuous">
        <origin xyz="-0.0007601800000000003 -0.00300003 -0.053999989999999796" rpy="-1.0587911840678752e-22 8.431962037770366e-33 4.224339667742767e-94" />
        <parent link="Part3_2" />
        <child link="Part2_3" />
        <axis xyz="-3.1554436245192396e-30 -0.9999999999999999 9.999999999999997e-07" />
        <mimic joint="Part3_1_gripper_joint_right1" multiplier="-1.0" offset="0.0"/>
    </joint>
    <!-- <joint name="Part1_2_gripper_joint_right8" type="continuous">
        <origin xyz="-0.008240160000000002 -0.003000009999999999 -0.020398520000000104" rpy="-5.293955920339378e-23 -0.0 -1.1102230246251565e-16" />
        <parent link="Part1_2" />
        <child link="Part2_3" />
        <axis xyz="0.0 1.0 -9.999999999999997e-07" />
    </joint> -->

    <joint name="Part3_1_gripper_joint_mimic" type="continuous">
        <origin xyz="-0.0075000000000000015 -0.03359971000000002 1.999999999946489e-08" rpy="1.5707963267948966 3.1554436208840472e-30 -3.150646851616307e-30" />
        <parent link="Part3_1" />
        <child link="Part5-1---ISO---Spur-Gear-1.125M-24T-20PA-3FW----S24A75H50L3.0N.ipt" />
        <axis xyz="3.155443616087278e-30 -1.0000000000000002 1.0000000000000002e-06" />
        <mimic joint="Part3_1_gripper_joint" multiplier="-1.0" offset="0.0"/>
    </joint>
    <joint name="Part3_1_gripper_joint_left1" type="continuous">
        <origin xyz="0.0007601799999999992 -0.053999999999999916 2.9999999999752445e-08" rpy="1.5707963267948966 3.1554436208840472e-30 -3.150646851616307e-30" />
        <parent link="Part3_1" />
        <child link="Part2_4" />
        <axis xyz="3.155443616087278e-30 -1.0000000000000002 1.0000000000000002e-06" />
        <mimic joint="Part3_1_gripper_joint_mimic" multiplier="1.0" offset="0.0"/>
    </joint>
    <joint name="Part5-1---ISO---Spur-Gear-1.125M-24T-20PA-3FW----S24A75H50L3.0N.ipt_gripper_joint_left2" type="continuous">
        <origin xyz="-0.0027018299999999984 2.000000000002e-08 0.030882039999999764" rpy="-2.646977644625326e-23 -1.5707963267948966 0" />
        <parent link="Part5-1---ISO---Spur-Gear-1.125M-24T-20PA-3FW----S24A75H50L3.0N.ipt" />
        <child link="Part1_3" />
        <axis xyz="-1.0000000000277557e-06 1.0000000000000002 2.6469779601696886e-23" />
        <mimic joint="Part3_1_gripper_joint_mimic" multiplier="1.0" offset="0.0"/>
    </joint>
    <!-- <joint name="Part2_4_gripper_joint_left3" type="continuous">
        <origin xyz="-0.00272185 2.000000000002e-08 0.030880279999999944" rpy="-9.92616735063633e-23 1.0587911840199075e-22 3.1554436208840465e-30" />
        <parent link="Part2_4" />
        <child link="Part1_3" />
        <axis xyz="-1.0587911840678754e-28 -0.9999999999999999 9.999999999999997e-07" />
    </joint> -->
    <joint name="Part1_3_gripper_joint_left4" type="fixed">
        <origin xyz="-1.4210854715202004e-16 0.002999999999999999 0.0" rpy="-2.7755575615628914e-17 1.5707963267948966 0" />
        <parent link="Part1_3" />
        <child link="Part1_4" />
    </joint>
    <joint name="Part3_2_gripper_joint_left5" type="continuous">
        <origin xyz="-0.019500000000000003 -0.00300002 -0.03359970999999987" rpy="-1.0587911840678752e-22 8.431962037770366e-33 4.224339667742767e-94" />
        <parent link="Part3_2" />
        <child link="Part2_5" />
        <axis xyz="-3.1554436245192396e-30 -0.9999999999999999 9.999999999999997e-07" />
        <mimic joint="Part3_1_gripper_joint_mimic" multiplier="-1.0" offset="0.0"/>
    </joint>
    <!-- <joint name="Part1_4_gripper_joint_left6" type="continuous">
        <origin xyz="0.0 0.0030000000000000005 0.0" rpy="1.0587911840678754e-22 -0.0 -1.1102230246251565e-16" />
        <parent link="Part1_4" />
        <child link="Part2_5" />
        <axis xyz="5.551115123115195e-17 -1.0 1e-06" />
    </joint> -->
    <joint name="Part3_2_gripper_joint_left7" type="continuous">
        <origin xyz="-0.011239819999999998 -0.00300003 -0.053999989999999796" rpy="-1.0587911840678752e-22 8.431962037770366e-33 4.224339667742767e-94" />
        <parent link="Part3_2" />
        <child link="Part2_6" />
        <axis xyz="-3.1554436245192396e-30 -0.9999999999999999 9.999999999999997e-07" />
        <mimic joint="Part3_1_gripper_joint_left1" multiplier="-1.0" offset="0.0"/>
    </joint>
    <!-- <joint name="Part1_4_gripper_joint_left8" type="continuous">
        <origin xyz="0.00824016 0.0030000099999999996 0.020398520000000104" rpy="1.0587911840678754e-22 -0.0 -1.1102230246251565e-16" />
        <parent link="Part1_4" />
        <child link="Part2_6" />
        <axis xyz="5.551115123115195e-17 -1.0 1e-06" />
    </joint> -->

    <joint name="Part3_2_gripper_joint_in" type="revolute">
        <origin xyz="0.0015000000000000002 -0.0028500099999999996 -0.014487749999999836" rpy="3.141592653589793 8.431962037770366e-33 4.224339667742767e-94" />
        <parent link="Part3_2" />
        <child link="Part8---ISO---Spur-gear-1M-13T-20PA-10FW----S13A75H50L0.8N.ipt" />
        <axis xyz="3.1554436245192396e-30 -0.9999999999999999 9.999999999999997e-07" />
        <limit lower="0.0" upper="2.899932" effort="1000000" velocity="1000000" />
        <mimic joint="Part3_1_gripper_joint" multiplier="-1.85" offset="0.0"/>
    </joint>
    <joint name="Part7_1_gripper_frame1" type="fixed">
        <origin xyz="-0.006 0.010999999999999944 -0.00800001" rpy="-3.141592653589793 -3.3409043112646216e-52 -3.1553949083981484e-30" />
        <parent link="Part7_1" />
        <child link="Part3_1" />
    </joint>
    <joint name="Part3_2_gripper_frame2" type="fixed">
        <origin xyz="-0.012 -0.003 1.0000000116860975e-08" rpy="-1.0587911840678752e-22 8.431962037770366e-33 4.224339667742767e-94" />
        <parent link="Part3_2" />
        <child link="Part7_2" />
    </joint>
    <joint name="mounting_plate_mount_gripper" type="fixed">
        <origin xyz="3.889952025007356e-34 0.01 0.010999989999999998" rpy="-4.037173576209384e-16 -3.863276849803671e-50 -9.569258699662684e-35" />
        <parent link="mounting_plate" />
        <child link="Part7_1" />
    </joint>
</robot>